2021-06-25 16:29:26,235 ERROR: Exception on /api_report [POST] [in c:\users\rmcra\splonkoreports\venv\lib\site-packages\flask\app.py:1454]
Traceback (most recent call last):
  File "c:\users\rmcra\splonkoreports\venv\lib\site-packages\flask\app.py", line 2070, in wsgi_app
    response = self.full_dispatch_request()
  File "c:\users\rmcra\splonkoreports\venv\lib\site-packages\flask\app.py", line 1515, in full_dispatch_request
    rv = self.handle_user_exception(e)
  File "c:\users\rmcra\splonkoreports\venv\lib\site-packages\flask\app.py", line 1513, in full_dispatch_request
    rv = self.dispatch_request()
  File "c:\users\rmcra\splonkoreports\venv\lib\site-packages\flask\app.py", line 1499, in dispatch_request
    return self.ensure_sync(self.view_functions[rule.endpoint])(**req.view_args)
  File "c:\users\rmcra\splonkoreports\venv\lib\site-packages\flask_login\utils.py", line 272, in decorated_view
    return func(*args, **kwargs)
  File "C:\Users\rmcra\SplonkoReports\app\routes.py", line 43, in api_report
    render_html(row)
  File "C:\Users\rmcra\SplonkoReports\app\report_generation.py", line 21, in render_html
    html_file = open(html_path, 'w')
FileNotFoundError: [Errno 2] No such file or directory: './res/List Users.html'
2021-06-25 16:30:00,846 INFO: Splonko startup [in C:\Users\rmcra\SplonkoReports\app\__init__.py:47]
2021-06-25 16:30:07,700 ERROR: Exception on /api_report [POST] [in c:\users\rmcra\splonkoreports\venv\lib\site-packages\flask\app.py:1454]
Traceback (most recent call last):
  File "c:\users\rmcra\splonkoreports\venv\lib\site-packages\flask\app.py", line 2070, in wsgi_app
    response = self.full_dispatch_request()
  File "c:\users\rmcra\splonkoreports\venv\lib\site-packages\flask\app.py", line 1515, in full_dispatch_request
    rv = self.handle_user_exception(e)
  File "c:\users\rmcra\splonkoreports\venv\lib\site-packages\flask\app.py", line 1513, in full_dispatch_request
    rv = self.dispatch_request()
  File "c:\users\rmcra\splonkoreports\venv\lib\site-packages\flask\app.py", line 1499, in dispatch_request
    return self.ensure_sync(self.view_functions[rule.endpoint])(**req.view_args)
  File "c:\users\rmcra\splonkoreports\venv\lib\site-packages\flask_login\utils.py", line 272, in decorated_view
    return func(*args, **kwargs)
  File "C:\Users\rmcra\SplonkoReports\app\routes.py", line 43, in api_report
    render_html(row)
  File "C:\Users\rmcra\SplonkoReports\app\report_generation.py", line 21, in render_html
    html_file = open(html_path, 'w')
FileNotFoundError: [Errno 2] No such file or directory: './pdf/List Users.html'
2021-06-25 16:30:35,207 INFO: Splonko startup [in C:\Users\rmcra\SplonkoReports\app\__init__.py:47]
2021-06-25 16:30:42,744 ERROR: Exception on /api_report [POST] [in c:\users\rmcra\splonkoreports\venv\lib\site-packages\flask\app.py:1454]
Traceback (most recent call last):
  File "c:\users\rmcra\splonkoreports\venv\lib\site-packages\flask\app.py", line 2070, in wsgi_app
    response = self.full_dispatch_request()
  File "c:\users\rmcra\splonkoreports\venv\lib\site-packages\flask\app.py", line 1515, in full_dispatch_request
    rv = self.handle_user_exception(e)
  File "c:\users\rmcra\splonkoreports\venv\lib\site-packages\flask\app.py", line 1513, in full_dispatch_request
    rv = self.dispatch_request()
  File "c:\users\rmcra\splonkoreports\venv\lib\site-packages\flask\app.py", line 1499, in dispatch_request
    return self.ensure_sync(self.view_functions[rule.endpoint])(**req.view_args)
  File "c:\users\rmcra\splonkoreports\venv\lib\site-packages\flask_login\utils.py", line 272, in decorated_view
    return func(*args, **kwargs)
  File "C:\Users\rmcra\SplonkoReports\app\routes.py", line 43, in api_report
    render_html(row)
  File "C:\Users\rmcra\SplonkoReports\app\report_generation.py", line 21, in render_html
    html_file = open(html_path, 'w')
OSError: [Errno 22] Invalid argument: './pdf/'
2021-06-25 16:30:54,600 INFO: Splonko startup [in C:\Users\rmcra\SplonkoReports\app\__init__.py:47]
2021-06-25 16:31:48,768 INFO: Splonko startup [in C:\Users\rmcra\SplonkoReports\app\__init__.py:47]
2021-06-25 16:33:46,438 INFO: Splonko startup [in C:\Users\rmcra\SplonkoReports\app\__init__.py:47]
2021-06-25 16:35:09,481 INFO: Splonko startup [in C:\Users\rmcra\SplonkoReports\app\__init__.py:47]
2021-06-25 16:35:14,946 ERROR: Exception on /api_report [POST] [in c:\users\rmcra\splonkoreports\venv\lib\site-packages\flask\app.py:1454]
Traceback (most recent call last):
  File "c:\users\rmcra\splonkoreports\venv\lib\site-packages\flask\app.py", line 2070, in wsgi_app
    response = self.full_dispatch_request()
  File "c:\users\rmcra\splonkoreports\venv\lib\site-packages\flask\app.py", line 1515, in full_dispatch_request
    rv = self.handle_user_exception(e)
  File "c:\users\rmcra\splonkoreports\venv\lib\site-packages\flask\app.py", line 1513, in full_dispatch_request
    rv = self.dispatch_request()
  File "c:\users\rmcra\splonkoreports\venv\lib\site-packages\flask\app.py", line 1499, in dispatch_request
    return self.ensure_sync(self.view_functions[rule.endpoint])(**req.view_args)
  File "c:\users\rmcra\splonkoreports\venv\lib\site-packages\flask_login\utils.py", line 272, in decorated_view
    return func(*args, **kwargs)
  File "C:\Users\rmcra\SplonkoReports\app\routes.py", line 43, in api_report
    render_html(row)
  File "C:\Users\rmcra\SplonkoReports\app\report_generation.py", line 21, in render_html
    html_file = open(html_path, 'w')
PermissionError: [Errno 13] Permission denied: '/pdf'
2021-06-25 16:35:31,690 INFO: Splonko startup [in C:\Users\rmcra\SplonkoReports\app\__init__.py:47]
2021-06-25 16:36:01,858 INFO: Splonko startup [in C:\Users\rmcra\SplonkoReports\app\__init__.py:47]
2021-06-25 16:37:39,394 INFO: Splonko startup [in C:\Users\rmcra\SplonkoReports\app\__init__.py:47]
2021-06-25 16:37:46,274 ERROR: Exception on /api_report [POST] [in c:\users\rmcra\splonkoreports\venv\lib\site-packages\flask\app.py:1454]
Traceback (most recent call last):
  File "c:\users\rmcra\splonkoreports\venv\lib\site-packages\flask\app.py", line 2070, in wsgi_app
    response = self.full_dispatch_request()
  File "c:\users\rmcra\splonkoreports\venv\lib\site-packages\flask\app.py", line 1515, in full_dispatch_request
    rv = self.handle_user_exception(e)
  File "c:\users\rmcra\splonkoreports\venv\lib\site-packages\flask\app.py", line 1513, in full_dispatch_request
    rv = self.dispatch_request()
  File "c:\users\rmcra\splonkoreports\venv\lib\site-packages\flask\app.py", line 1499, in dispatch_request
    return self.ensure_sync(self.view_functions[rule.endpoint])(**req.view_args)
  File "c:\users\rmcra\splonkoreports\venv\lib\site-packages\flask_login\utils.py", line 272, in decorated_view
    return func(*args, **kwargs)
  File "C:\Users\rmcra\SplonkoReports\app\routes.py", line 43, in api_report
    render_html(row)
  File "C:\Users\rmcra\SplonkoReports\app\report_generation.py", line 20, in render_html
    html_file = open(html_path, 'w')
PermissionError: [Errno 13] Permission denied: './app/pdf'
2021-06-25 16:37:51,252 ERROR: Exception on /api_report [POST] [in c:\users\rmcra\splonkoreports\venv\lib\site-packages\flask\app.py:1454]
Traceback (most recent call last):
  File "c:\users\rmcra\splonkoreports\venv\lib\site-packages\flask\app.py", line 2070, in wsgi_app
    response = self.full_dispatch_request()
  File "c:\users\rmcra\splonkoreports\venv\lib\site-packages\flask\app.py", line 1515, in full_dispatch_request
    rv = self.handle_user_exception(e)
  File "c:\users\rmcra\splonkoreports\venv\lib\site-packages\flask\app.py", line 1513, in full_dispatch_request
    rv = self.dispatch_request()
  File "c:\users\rmcra\splonkoreports\venv\lib\site-packages\flask\app.py", line 1499, in dispatch_request
    return self.ensure_sync(self.view_functions[rule.endpoint])(**req.view_args)
  File "c:\users\rmcra\splonkoreports\venv\lib\site-packages\flask_login\utils.py", line 272, in decorated_view
    return func(*args, **kwargs)
  File "C:\Users\rmcra\SplonkoReports\app\routes.py", line 43, in api_report
    render_html(row)
  File "C:\Users\rmcra\SplonkoReports\app\report_generation.py", line 20, in render_html
    html_file = open(html_path, 'w')
PermissionError: [Errno 13] Permission denied: './app/pdf'
2021-06-25 16:38:09,251 INFO: Splonko startup [in C:\Users\rmcra\SplonkoReports\app\__init__.py:47]
2021-06-25 16:38:13,843 ERROR: Exception on /api_report [POST] [in c:\users\rmcra\splonkoreports\venv\lib\site-packages\flask\app.py:1454]
Traceback (most recent call last):
  File "c:\users\rmcra\splonkoreports\venv\lib\site-packages\flask\app.py", line 2070, in wsgi_app
    response = self.full_dispatch_request()
  File "c:\users\rmcra\splonkoreports\venv\lib\site-packages\flask\app.py", line 1515, in full_dispatch_request
    rv = self.handle_user_exception(e)
  File "c:\users\rmcra\splonkoreports\venv\lib\site-packages\flask\app.py", line 1513, in full_dispatch_request
    rv = self.dispatch_request()
  File "c:\users\rmcra\splonkoreports\venv\lib\site-packages\flask\app.py", line 1499, in dispatch_request
    return self.ensure_sync(self.view_functions[rule.endpoint])(**req.view_args)
  File "c:\users\rmcra\splonkoreports\venv\lib\site-packages\flask_login\utils.py", line 272, in decorated_view
    return func(*args, **kwargs)
  File "C:\Users\rmcra\SplonkoReports\app\routes.py", line 43, in api_report
    render_html(row)
  File "C:\Users\rmcra\SplonkoReports\app\report_generation.py", line 20, in render_html
    html_file = open(html_path, 'w')
FileNotFoundError: [Errno 2] No such file or directory: '/app/pdf'
2021-06-25 16:38:45,449 INFO: Splonko startup [in C:\Users\rmcra\SplonkoReports\app\__init__.py:47]
