2021-06-25 09:34:49,672 ERROR: Exception on /edit_api [POST] [in c:\users\rmcra\splonkoreports\venv\lib\site-packages\flask\app.py:1454]
Traceback (most recent call last):
  File "c:\users\rmcra\splonkoreports\venv\lib\site-packages\flask\app.py", line 2070, in wsgi_app
    response = self.full_dispatch_request()
  File "c:\users\rmcra\splonkoreports\venv\lib\site-packages\flask\app.py", line 1515, in full_dispatch_request
    rv = self.handle_user_exception(e)
  File "c:\users\rmcra\splonkoreports\venv\lib\site-packages\flask\app.py", line 1513, in full_dispatch_request
    rv = self.dispatch_request()
  File "c:\users\rmcra\splonkoreports\venv\lib\site-packages\flask\app.py", line 1499, in dispatch_request
    return self.ensure_sync(self.view_functions[rule.endpoint])(**req.view_args)
  File "c:\users\rmcra\splonkoreports\venv\lib\site-packages\flask_login\utils.py", line 272, in decorated_view
    return func(*args, **kwargs)
  File "C:\Users\rmcra\SplonkoReports\app\routes.py", line 201, in edit_api
    print('Data is ' + requesttype + ' ' + apiurl + ' ' + apidata, file=sys.stderr)
TypeError: can only concatenate str (not "NoneType") to str
2021-06-25 09:35:47,492 ERROR: Exception on /edit_api [POST] [in c:\users\rmcra\splonkoreports\venv\lib\site-packages\flask\app.py:1454]
Traceback (most recent call last):
  File "c:\users\rmcra\splonkoreports\venv\lib\site-packages\flask\app.py", line 2070, in wsgi_app
    response = self.full_dispatch_request()
  File "c:\users\rmcra\splonkoreports\venv\lib\site-packages\flask\app.py", line 1515, in full_dispatch_request
    rv = self.handle_user_exception(e)
  File "c:\users\rmcra\splonkoreports\venv\lib\site-packages\flask\app.py", line 1513, in full_dispatch_request
    rv = self.dispatch_request()
  File "c:\users\rmcra\splonkoreports\venv\lib\site-packages\flask\app.py", line 1499, in dispatch_request
    return self.ensure_sync(self.view_functions[rule.endpoint])(**req.view_args)
  File "c:\users\rmcra\splonkoreports\venv\lib\site-packages\flask_login\utils.py", line 272, in decorated_view
    return func(*args, **kwargs)
  File "C:\Users\rmcra\SplonkoReports\app\routes.py", line 201, in edit_api
    print('Data is ' + requesttype + ' ' + apiurl + ' ' + apidata, file=sys.stderr)
TypeError: can only concatenate str (not "NoneType") to str
2021-06-25 09:38:36,298 ERROR: Exception on /index [GET] [in c:\users\rmcra\splonkoreports\venv\lib\site-packages\flask\app.py:1454]
Traceback (most recent call last):
  File "C:\Users\rmcra\SplonkoReports\app\requests_helper.py", line 23, in perform_request
    response = requests.put(requesturl, requestdata)
  File "c:\users\rmcra\splonkoreports\venv\lib\site-packages\pip\_vendor\requests\api.py", line 134, in put
    return request('put', url, data=data, **kwargs)
  File "c:\users\rmcra\splonkoreports\venv\lib\site-packages\pip\_vendor\requests\api.py", line 61, in request
    return session.request(method=method, url=url, **kwargs)
  File "c:\users\rmcra\splonkoreports\venv\lib\site-packages\pip\_vendor\requests\sessions.py", line 528, in request
    prep = self.prepare_request(req)
  File "c:\users\rmcra\splonkoreports\venv\lib\site-packages\pip\_vendor\requests\sessions.py", line 456, in prepare_request
    p.prepare(
  File "c:\users\rmcra\splonkoreports\venv\lib\site-packages\pip\_vendor\requests\models.py", line 316, in prepare
    self.prepare_url(url, params)
  File "c:\users\rmcra\splonkoreports\venv\lib\site-packages\pip\_vendor\requests\models.py", line 390, in prepare_url
    raise MissingSchema(error)
pip._vendor.requests.exceptions.MissingSchema: Invalid URL 'test': No schema supplied. Perhaps you meant http://test?

During handling of the above exception, another exception occurred:

Traceback (most recent call last):
  File "c:\users\rmcra\splonkoreports\venv\lib\site-packages\flask\app.py", line 2070, in wsgi_app
    response = self.full_dispatch_request()
  File "c:\users\rmcra\splonkoreports\venv\lib\site-packages\flask\app.py", line 1515, in full_dispatch_request
    rv = self.handle_user_exception(e)
  File "c:\users\rmcra\splonkoreports\venv\lib\site-packages\flask\app.py", line 1513, in full_dispatch_request
    rv = self.dispatch_request()
  File "c:\users\rmcra\splonkoreports\venv\lib\site-packages\flask\app.py", line 1499, in dispatch_request
    return self.ensure_sync(self.view_functions[rule.endpoint])(**req.view_args)
  File "c:\users\rmcra\splonkoreports\venv\lib\site-packages\flask_login\utils.py", line 272, in decorated_view
    return func(*args, **kwargs)
  File "C:\Users\rmcra\SplonkoReports\app\routes.py", line 35, in index
    response = requests_helper.perform_request(requesttype, apiurl, apidata)
  File "C:\Users\rmcra\SplonkoReports\app\requests_helper.py", line 26, in perform_request
    response = requests.put(requesturl, requestdata).text
  File "c:\users\rmcra\splonkoreports\venv\lib\site-packages\pip\_vendor\requests\api.py", line 134, in put
    return request('put', url, data=data, **kwargs)
  File "c:\users\rmcra\splonkoreports\venv\lib\site-packages\pip\_vendor\requests\api.py", line 61, in request
    return session.request(method=method, url=url, **kwargs)
  File "c:\users\rmcra\splonkoreports\venv\lib\site-packages\pip\_vendor\requests\sessions.py", line 528, in request
    prep = self.prepare_request(req)
  File "c:\users\rmcra\splonkoreports\venv\lib\site-packages\pip\_vendor\requests\sessions.py", line 456, in prepare_request
    p.prepare(
  File "c:\users\rmcra\splonkoreports\venv\lib\site-packages\pip\_vendor\requests\models.py", line 316, in prepare
    self.prepare_url(url, params)
  File "c:\users\rmcra\splonkoreports\venv\lib\site-packages\pip\_vendor\requests\models.py", line 390, in prepare_url
    raise MissingSchema(error)
pip._vendor.requests.exceptions.MissingSchema: Invalid URL 'test': No schema supplied. Perhaps you meant http://test?
2021-06-25 09:40:36,306 INFO: Splonko startup [in C:\Users\rmcra\SplonkoReports\app\__init__.py:47]
2021-06-25 09:41:25,760 INFO: Splonko startup [in C:\Users\rmcra\SplonkoReports\app\__init__.py:47]
